<?xml version="1.0" ?>
<!-- =================================================================================== -->
<!-- |    This document was autogenerated by xacro from sirius_mid_ax1_mpc.xacro       | -->
<!-- |    EDITING THIS FILE BY HAND IS NOT RECOMMENDED                                 | -->
<!-- =================================================================================== -->
<robot name="qm">
  <gazebo>
    <plugin filename="libgazebo_ros_p3d.so" name="p3d_base_controller">
      <alwaysOn>true</alwaysOn>
      <updateRate>1000.0</updateRate>
      <bodyName>base</bodyName>
      <topicName>ground_truth/state</topicName>
      <gaussianNoise>0</gaussianNoise>
      <frameName>world</frameName>
      <xyzOffsets>0 0 0</xyzOffsets>
      <rpyOffsets>0 0 0</rpyOffsets>
    </plugin>
  </gazebo>
  <gazebo reference="base">
    <gravity>true</gravity>
    <sensor name="imu_sensor" type="imu">
      <always_on>true</always_on>
      <update_rate>1000</update_rate>
      <visualize>true</visualize>
      <topic>__default_topic__</topic>
      <plugin filename="libgazebo_ros_imu_sensor.so" name="imu_plugin">
        <topicName>imu</topicName>
        <bodyName>base</bodyName>
        <updateRateHZ>1000.0</updateRateHZ>
        <gaussianNoise>0.0</gaussianNoise>
        <xyzOffset>0 0 0</xyzOffset>
        <rpyOffset>0 0 0</rpyOffset>
        <frameName>base</frameName>
        <initialOrientationAsReference>false</initialOrientationAsReference>
      </plugin>
      <pose>0 0 0 0 0 0</pose>
    </sensor>
  </gazebo>
  <gazebo reference="LF_FOOT">
    <mu1>0.6</mu1>
    <mu2>0.6</mu2>
    <self_collide>1</self_collide>
    <material>Gazebo/DarkGrey</material>
    <kp value="1000000.0"/>
    <kd value="100.0"/>
  </gazebo>
  <gazebo reference="RF_FOOT">
    <mu1>0.6</mu1>
    <mu2>0.6</mu2>
    <self_collide>1</self_collide>
    <material>Gazebo/DarkGrey</material>
    <kp value="1000000.0"/>
    <kd value="100.0"/>
  </gazebo>
  <gazebo reference="LH_FOOT">
    <mu1>0.6</mu1>
    <mu2>0.6</mu2>
    <self_collide>1</self_collide>
    <material>Gazebo/DarkGrey</material>
    <kp value="1000000.0"/>
    <kd value="100.0"/>
  </gazebo>
  <gazebo reference="RH_FOOT">
    <mu1>0.6</mu1>
    <mu2>0.6</mu2>
    <self_collide>1</self_collide>
    <material>Gazebo/DarkGrey</material>
    <kp value="1000000.0"/>
    <kd value="100.0"/>
  </gazebo>
  <!-- Imu is fixed to the base link -->
  <joint name="unitree_imu_joint" type="fixed">
    <origin rpy="0. 0. 0." xyz="0. 0. 0."/>
    <parent link="base"/>
    <child link="unitree_imu"/>
  </joint>
  <!-- Imu link -->
  <link name="unitree_imu">
    <inertial>
      <mass value="0.01"/>
      <origin rpy="0 0 0" xyz="0 0 0"/>
      <inertia ixx="0.000001" ixy="0" ixz="0" iyy="0.000001" iyz="0" izz="0.000001"/>
    </inertial>
    <visual>
      <origin rpy="0 0 0" xyz="0 0 0"/>
      <geometry>
        <box size="0.015 0.015 0.004"/>
      </geometry>
    </visual>
    <material name="orange">
      <color rgba="255 108 10 255"/>
    </material>
  </link>
  <gazebo reference="unitree_imu">
    <material>Gazebo/Orange</material>
  </gazebo>
  <gazebo reference="unitree_imu_joint">
    <disableFixedJointLumping>true</disableFixedJointLumping>
  </gazebo>
  <link name="base">
    <inertial>
      <origin rpy="0 0 0" xyz="0.0446334 0.0002693 -0.0071156"/>
      <mass value="12.149"/>
      <inertia ixx="0.048576" ixy="-6.6872E-05" ixz="-0.00070888" iyy="0.75312" iyz="-0.00029442" izz="0.75287"/>
    </inertial>
    <visual>
      <origin rpy="0 0 0" xyz="0 0 0"/>
      <geometry>
        <mesh filename="package://qm_description/meshes/qudraputed/sirius/base_link.STL"/>
      </geometry>
      <material name="">
        <color rgba="0.69804 0.69804 0.69804 1"/>
      </material>
    </visual>
    <collision>
      <origin rpy="0 0 0" xyz="0 0 0"/>
      <geometry>
        <!-- <mesh
          filename="package://qm_description/meshes/qudraputed/$(arg robot_type)/base_link.STL" /> -->
        <box size="0.48200 0.21200 0.11200"/>
      </geometry>
    </collision>
  </link>
  <link name="difference_fr">
    <inertial>
      <origin rpy="0 0 0" xyz="2.76255611664222E-07 0.00678503293494918 -7.28949860936864E-05"/>
      <mass value="1.83991949808533"/>
      <inertia ixx="0.00159669309110301" ixy="2.40619784879463E-08" ixz="7.04421309599189E-10" iyy="0.00218039802623776" iyz="4.40635676564122E-06" izz="0.0024879385019285"/>
    </inertial>
    <visual>
      <origin rpy="0 0 0" xyz="0 0 0"/>
      <geometry>
        <mesh filename="package://qm_description/meshes/qudraputed/sirius/difference_fr.STL"/>
      </geometry>
      <material name="">
        <color rgba="0.698039215686274 0.698039215686274 0.698039215686274 1"/>
      </material>
    </visual>
    <!-- <collision>
      <origin
        xyz="0 0 0"
        rpy="0 0 0" />
      <geometry>
        <mesh
          filename="package://qm_description/meshes/qudraputed/$(arg robot_type)/difference_fr.STL" />
      </geometry>
    </collision> -->
  </link>
  <joint name="LF_HAA" type="revolute">
    <origin rpy="0 0 0" xyz="0.31 0.05 0"/>
    <parent link="base"/>
    <child link="difference_fr"/>
    <axis xyz="1 0 0"/>
    <dynamics damping="0.0" friction="0.0"/>
    <limit effort="35" lower="-0.7853981633974483" upper="0.7853981633974483" velocity="45"/>
  </joint>
  <link name="thigh_fr">
    <inertial>
      <origin rpy="0 0 0" xyz="7.80050075943617E-06 0.0767248973446957 -0.0853108309031699"/>
      <mass value="1.84491872524247"/>
      <inertia ixx="0.0200731328399129" ixy="-6.22649349293949E-06" ixz="-1.64601580051228E-05" iyy="0.0194374035044485" iyz="0.00239094298924952" izz="0.0025429424909611"/>
    </inertial>
    <visual>
      <origin rpy="0 0 0" xyz="0 0 0"/>
      <geometry>
        <mesh filename="package://qm_description/meshes/qudraputed/sirius/thigh_fr.STL"/>
      </geometry>
      <material name="">
        <color rgba="0.698039215686274 0.698039215686274 0.698039215686274 1"/>
      </material>
    </visual>
    <collision>
      <origin rpy="0 0 0" xyz="0 0.093 -0.135"/>
      <geometry>
        <box size="0.05 0.04 0.28"/>
        <!-- <mesh
          filename="package://qm_description/meshes/qudraputed/$(arg robot_type)/thigh_fr.STL" /> -->
      </geometry>
    </collision>
  </link>
  <joint name="LF_HFE" type="revolute">
    <origin rpy="0 0 0" xyz="0 0.0415 0"/>
    <parent link="difference_fr"/>
    <child link="thigh_fr"/>
    <axis xyz="0 1 0"/>
    <dynamics damping="0.0" friction="0.0"/>
    <limit effort="35" lower="-1.57" upper="1.57" velocity="45"/>
  </joint>
  <link name="shank_fr">
    <inertial>
      <origin rpy="0 0 0" xyz="-0.0379180936704923 -1.00823098490022E-05 -0.105367936306375"/>
      <mass value="0.46394589686281"/>
      <inertia ixx="0.0062901661243756" ixy="-1.45795386191276E-07" ixz="-0.00134757706117442" iyy="0.00676703648405088" iyz="-7.33331301121544E-07" izz="0.000568017818716471"/>
    </inertial>
    <visual>
      <origin rpy="0 0 0" xyz="0 0 0"/>
      <geometry>
        <mesh filename="package://qm_description/meshes/qudraputed/sirius/shank_fr.STL"/>
      </geometry>
      <material name="">
        <color rgba="0.698039215686274 0.698039215686274 0.698039215686274 1"/>
      </material>
    </visual>
    <collision>
      <origin rpy="0 0 0" xyz="-0.055 0 -0.12"/>
      <geometry>
        <cylinder length="0.25" radius="0.016"/>
        <!-- <mesh
          filename="package://qm_description/meshes/qudraputed/$(arg robot_type)/shank_fr.STL" /> -->
      </geometry>
    </collision>
  </link>
  <joint name="LF_KFE" type="revolute">
    <origin rpy="0 0 0" xyz="0 0.0931000000000018 -0.270122814075178"/>
    <parent link="thigh_fr"/>
    <child link="shank_fr"/>
    <axis xyz="0 1 0"/>
    <dynamics damping="0.0" friction="0.0"/>
    <limit effort="45" lower="-3.141592653589793" upper="1.17453292519943295" velocity="45"/>
  </joint>
  <link name="LF_FOOT">
    <visual>
      <origin rpy="0 0 0" xyz="0 0 0"/>
      <geometry>
        <sphere radius="0.03"/>
      </geometry>
      <!-- <material name="orange"/> -->
    </visual>
    <collision>
      <origin rpy="0 0 0" xyz="0 0 0"/>
      <geometry>
        <sphere radius="0.03"/>
      </geometry>
    </collision>
    <inertial>
      <mass value="0.06"/>
      <inertia ixx="9.600000000000001e-04" ixy="0.0" ixz="0.0" iyy="9.600000000000001e-04" iyz="0.0" izz="9.600000000000001e-03"/>
    </inertial>
  </link>
  <joint name="LF_FOOT_fixed_joint" type="fixed">
    <origin rpy="0 0 0" xyz="-0.07 0 -0.252"/>
    <parent link="shank_fr"/>
    <child link="LF_FOOT"/>
  </joint>
  <transmission name="LF_HAA_tran">
    <type>transmission_interface/SimpleTransmission</type>
    <joint name="LF_HAA">
      <hardwareInterface>hardware_interface/EffortJointInterface</hardwareInterface>
    </joint>
    <actuator name="LF_HAA_motor">
      <hardwareInterface>hardware_interface/EffortJointInterface</hardwareInterface>
      <mechanicalReduction>1</mechanicalReduction>
    </actuator>
  </transmission>
  <transmission name="LF_HFE_tran">
    <type>transmission_interface/SimpleTransmission</type>
    <joint name="LF_HFE">
      <hardwareInterface>hardware_interface/EffortJointInterface</hardwareInterface>
    </joint>
    <actuator name="LF_HFE_motor">
      <hardwareInterface>hardware_interface/EffortJointInterface</hardwareInterface>
      <mechanicalReduction>1</mechanicalReduction>
    </actuator>
  </transmission>
  <transmission name="LF_KFE_tran">
    <type>transmission_interface/SimpleTransmission</type>
    <joint name="LF_KFE">
      <hardwareInterface>hardware_interface/EffortJointInterface</hardwareInterface>
    </joint>
    <actuator name="LF_KFE_motor">
      <hardwareInterface>hardware_interface/EffortJointInterface</hardwareInterface>
      <mechanicalReduction>1</mechanicalReduction>
    </actuator>
  </transmission>
  <link name="difference_br">
    <inertial>
      <origin rpy="0 0 0" xyz="2.76255611664222E-07 0.0067850329349492 -7.28949860947287E-05"/>
      <mass value="1.83991949808533"/>
      <inertia ixx="0.00159669309110302" ixy="2.4061978488582E-08" ixz="7.04421309293951E-10" iyy="0.00218039802623776" iyz="4.40635676564146E-06" izz="0.0024879385019285"/>
    </inertial>
    <visual>
      <origin rpy="0 0 0" xyz="0 0 0"/>
      <geometry>
        <mesh filename="package://qm_description/meshes/qudraputed/sirius/difference_br.STL"/>
      </geometry>
      <material name="">
        <color rgba="0.698039215686274 0.698039215686274 0.698039215686274 1"/>
      </material>
    </visual>
    <!-- <collision>
      <origin
        xyz="0 0 0"
        rpy="0 0 0" />
      <geometry>
        <mesh
          filename="package://qm_description/meshes/qudraputed/$(arg robot_type)/difference_br.STL" />
      </geometry>
    </collision> -->
  </link>
  <joint name="LH_HAA" type="revolute">
    <origin rpy="0 0 0" xyz="-0.31 0.05 0"/>
    <parent link="base"/>
    <child link="difference_br"/>
    <axis xyz="1 0 0"/>
    <dynamics damping="0.0" friction="0.0"/>
    <limit effort="35" lower="-0.7853981633974483" upper="0.7853981633974483" velocity="45"/>
  </joint>
  <link name="thigh_br">
    <inertial>
      <origin rpy="0 0 0" xyz="7.80050034682178E-06 0.0767248973447084 -0.0853108309031707"/>
      <mass value="1.84491872524246"/>
      <inertia ixx="0.0200731328399129" ixy="-6.22649349294517E-06" ixz="-1.64601580051122E-05" iyy="0.0194374035044485" iyz="0.00239094298924952" izz="0.00254294249096109"/>
    </inertial>
    <visual>
      <origin rpy="0 0 0" xyz="0 0 0"/>
      <geometry>
        <mesh filename="package://qm_description/meshes/qudraputed/sirius/thigh_br.STL"/>
      </geometry>
      <material name="">
        <color rgba="0.698039215686274 0.698039215686274 0.698039215686274 1"/>
      </material>
    </visual>
    <collision>
      <origin rpy="0 0 0" xyz="0 0.093 -0.135"/>
      <geometry>
        <box size="0.05 0.04 0.28"/>
        <!-- <mesh
          filename="package://qm_description/meshes/qudraputed/$(arg robot_type)/thigh_br.STL" /> -->
      </geometry>
    </collision>
  </link>
  <joint name="LH_HFE" type="revolute">
    <origin rpy="0 0 0" xyz="0 0.0414999999974441 0"/>
    <parent link="difference_br"/>
    <child link="thigh_br"/>
    <axis xyz="0 1 0"/>
    <dynamics damping="0.0" friction="0.0"/>
    <limit effort="35" lower="-1.57" upper="1.57" velocity="45"/>
  </joint>
  <link name="shank_br">
    <inertial>
      <origin rpy="0 0 0" xyz="0.0379180936765431 1.00823142355488E-05 -0.105367936359481"/>
      <mass value="0.463945897140413"/>
      <inertia ixx="0.00629016612668043" ixy="-1.45795411298519E-07" ixz="0.00134757706144971" iyy="0.00676703648637542" iyz="7.33331493810339E-07" izz="0.000568017818767203"/>
    </inertial>
    <visual>
      <origin rpy="0 0 0" xyz="0 0 0"/>
      <geometry>
        <mesh filename="package://qm_description/meshes/qudraputed/sirius/shank_br.STL"/>
      </geometry>
      <material name="">
        <color rgba="0.698039215686274 0.698039215686274 0.698039215686274 1"/>
      </material>
    </visual>
    <collision>
      <origin rpy="0 0 0" xyz="0.055 0 -0.12"/>
      <geometry>
        <cylinder length="0.25" radius="0.016"/>
        <!-- <mesh
          filename="package://qm_description/meshes/qudraputed/$(arg robot_type)/shank_br.STL" /> -->
      </geometry>
    </collision>
  </link>
  <joint name="LH_KFE" type="revolute">
    <origin rpy="0 0 0" xyz="0 0.0931000000000196 -0.270122814075249"/>
    <parent link="thigh_br"/>
    <child link="shank_br"/>
    <axis xyz="0 1 0"/>
    <dynamics damping="0.0" friction="0.0"/>
    <limit effort="45" lower="-1.17453292519943295" upper="3.141592653589793" velocity="45"/>
  </joint>
  <link name="LH_FOOT">
    <visual>
      <origin rpy="0 0 0" xyz="0 0 0"/>
      <geometry>
        <sphere radius="0.03"/>
      </geometry>
      <!-- <material name="orange"/> -->
    </visual>
    <collision>
      <origin rpy="0 0 0" xyz="0 0 0"/>
      <geometry>
        <sphere radius="0.03"/>
      </geometry>
    </collision>
    <inertial>
      <mass value="0.06"/>
      <inertia ixx="9.600000000000001e-04" ixy="0.0" ixz="0.0" iyy="9.600000000000001e-04" iyz="0.0" izz="9.600000000000001e-03"/>
    </inertial>
  </link>
  <joint name="LH_FOOT_fixed_joint" type="fixed">
    <origin rpy="0 0 0" xyz="0.07 0 -0.252"/>
    <parent link="shank_br"/>
    <child link="LH_FOOT"/>
  </joint>
  <transmission name="LH_HAA_tran">
    <type>transmission_interface/SimpleTransmission</type>
    <joint name="LH_HAA">
      <hardwareInterface>hardware_interface/EffortJointInterface</hardwareInterface>
    </joint>
    <actuator name="LH_HAA_motor">
      <hardwareInterface>hardware_interface/EffortJointInterface</hardwareInterface>
      <mechanicalReduction>1</mechanicalReduction>
    </actuator>
  </transmission>
  <transmission name="LH_HFE_tran">
    <type>transmission_interface/SimpleTransmission</type>
    <joint name="LH_HFE">
      <hardwareInterface>hardware_interface/EffortJointInterface</hardwareInterface>
    </joint>
    <actuator name="LH_HFE_motor">
      <hardwareInterface>hardware_interface/EffortJointInterface</hardwareInterface>
      <mechanicalReduction>1</mechanicalReduction>
    </actuator>
  </transmission>
  <transmission name="LH_KFE_tran">
    <type>transmission_interface/SimpleTransmission</type>
    <joint name="LH_KFE">
      <hardwareInterface>hardware_interface/EffortJointInterface</hardwareInterface>
    </joint>
    <actuator name="LH_KFE_motor">
      <hardwareInterface>hardware_interface/EffortJointInterface</hardwareInterface>
      <mechanicalReduction>1</mechanicalReduction>
    </actuator>
  </transmission>
  <link name="difference_fl">
    <inertial>
      <origin rpy="0 0 0" xyz="-2.74870503469415E-07 -0.00678503161175874 -7.28954687522767E-05"/>
      <mass value="1.83991942523528"/>
      <inertia ixx="0.00159669300620188" ixy="2.40834466841156E-08" ixz="-6.36563017347744E-10" iyy="0.00218039794501133" iyz="-4.40637299692243E-06" izz="0.00248793843492296"/>
    </inertial>
    <visual>
      <origin rpy="0 0 0" xyz="0 0 0"/>
      <geometry>
        <mesh filename="package://qm_description/meshes/qudraputed/sirius/difference_fl.STL"/>
      </geometry>
      <material name="">
        <color rgba="0.698039215686274 0.698039215686274 0.698039215686274 1"/>
      </material>
    </visual>
    <!-- <collision>
      <origin
        xyz="0 0 0"
        rpy="0 0 0" />
      <geometry>
        <mesh
          filename="package://qm_description/meshes/qudraputed/$(arg robot_type)/difference_fl.STL" />
      </geometry>
    </collision> -->
  </link>
  <joint name="RF_HAA" type="revolute">
    <origin rpy="0 0 0" xyz="0.31 -0.05 0"/>
    <parent link="base"/>
    <child link="difference_fl"/>
    <axis xyz="1 0 0"/>
    <dynamics damping="0.0" friction="0.0"/>
    <limit effort="35" lower="-0.7853981633974483" upper="0.7853981633974483" velocity="45"/>
  </joint>
  <link name="thigh_fl">
    <inertial>
      <origin rpy="0 0 0" xyz="-7.79361510067078E-06 -0.0767249033075051 -0.0853108141844979"/>
      <mass value="1.84491923543637"/>
      <inertia ixx="0.0200731337773401" ixy="-6.22617105712194E-06" ixz="1.64593347132117E-05" iyy="0.0194374045436634" iyz="-0.00239094217884282" izz="0.00254294323646131"/>
    </inertial>
    <visual>
      <origin rpy="0 0 0" xyz="0 0 0"/>
      <geometry>
        <mesh filename="package://qm_description/meshes/qudraputed/sirius/thigh_fl.STL"/>
      </geometry>
      <material name="">
        <color rgba="0.698039215686274 0.698039215686274 0.698039215686274 1"/>
      </material>
    </visual>
    <collision>
      <origin rpy="0 0 0" xyz="0 -0.093 -0.135"/>
      <geometry>
        <box size="0.05 0.04 0.28"/>
        <!-- <mesh
          filename="package://qm_description/meshes/qudraputed/$(arg robot_type)/thigh_fl.STL" /> -->
      </geometry>
    </collision>
  </link>
  <joint name="RF_HFE" type="revolute">
    <origin rpy="0 0 0" xyz="0 -0.0415000000000005 0"/>
    <parent link="difference_fl"/>
    <child link="thigh_fl"/>
    <axis xyz="0 1 0"/>
    <dynamics damping="0.0" friction="0.0"/>
    <limit effort="35" lower="-1.57" upper="1.57" velocity="45"/>
  </joint>
  <link name="shank_fl">
    <inertial>
      <origin rpy="0 0 0" xyz="-0.0379180936720089 -1.00823109106252E-05 -0.105367936319631"/>
      <mass value="0.463945896932349"/>
      <inertia ixx="0.00629016612495341" ixy="-1.45795391992759E-07" ixz="-0.0013475770612434" iyy="0.00676703648463362" iyz="-7.33331348046914E-07" izz="0.00056801781872918"/>
    </inertial>
    <visual>
      <origin rpy="0 0 0" xyz="0 0 0"/>
      <geometry>
        <mesh filename="package://qm_description/meshes/qudraputed/sirius/shank_fl.STL"/>
      </geometry>
      <material name="">
        <color rgba="0.698039215686274 0.698039215686274 0.698039215686274 1"/>
      </material>
    </visual>
    <collision>
      <origin rpy="0 0 0" xyz="-0.055 0 -0.12"/>
      <geometry>
        <cylinder length="0.25" radius="0.016"/>
        <!-- <mesh
          filename="package://qm_description/meshes/qudraputed/$(arg robot_type)/shank_fl.STL" /> -->
      </geometry>
    </collision>
  </link>
  <joint name="RF_KFE" type="revolute">
    <origin rpy="0 0 0" xyz="0 -0.0931000000000001 -0.270122814075249"/>
    <parent link="thigh_fl"/>
    <child link="shank_fl"/>
    <axis xyz="0 1 0"/>
    <dynamics damping="0.0" friction="0.0"/>
    <limit effort="45" lower="-3.141592653589793" upper="1.17453292519943295" velocity="45"/>
  </joint>
  <link name="RF_FOOT">
    <visual>
      <origin rpy="0 0 0" xyz="0 0 0"/>
      <geometry>
        <sphere radius="0.03"/>
      </geometry>
      <!-- <material name="orange"/> -->
    </visual>
    <collision>
      <origin rpy="0 0 0" xyz="0 0 0"/>
      <geometry>
        <sphere radius="0.03"/>
      </geometry>
    </collision>
    <inertial>
      <mass value="0.06"/>
      <inertia ixx="9.600000000000001e-04" ixy="0.0" ixz="0.0" iyy="9.600000000000001e-04" iyz="0.0" izz="9.600000000000001e-03"/>
    </inertial>
  </link>
  <joint name="RF_FOOT_fixed_joint" type="fixed">
    <origin rpy="0 0 0" xyz="-0.07 0 -0.252"/>
    <parent link="shank_fl"/>
    <child link="RF_FOOT"/>
  </joint>
  <transmission name="RF_HAA_tran">
    <type>transmission_interface/SimpleTransmission</type>
    <joint name="RF_HAA">
      <hardwareInterface>hardware_interface/EffortJointInterface</hardwareInterface>
    </joint>
    <actuator name="RF_HAA_motor">
      <hardwareInterface>hardware_interface/EffortJointInterface</hardwareInterface>
      <mechanicalReduction>1</mechanicalReduction>
    </actuator>
  </transmission>
  <transmission name="RF_HFE_tran">
    <type>transmission_interface/SimpleTransmission</type>
    <joint name="RF_HFE">
      <hardwareInterface>hardware_interface/EffortJointInterface</hardwareInterface>
    </joint>
    <actuator name="RF_HFE_motor">
      <hardwareInterface>hardware_interface/EffortJointInterface</hardwareInterface>
      <mechanicalReduction>1</mechanicalReduction>
    </actuator>
  </transmission>
  <transmission name="RF_KFE_tran">
    <type>transmission_interface/SimpleTransmission</type>
    <joint name="RF_KFE">
      <hardwareInterface>hardware_interface/EffortJointInterface</hardwareInterface>
    </joint>
    <actuator name="RF_KFE_motor">
      <hardwareInterface>hardware_interface/EffortJointInterface</hardwareInterface>
      <mechanicalReduction>1</mechanicalReduction>
    </actuator>
  </transmission>
  <link name="difference_bl">
    <inertial>
      <origin rpy="0 0 0" xyz="2.76255611664222E-07 0.0067850329349492 -7.28949860947287E-05"/>
      <mass value="1.83991949808533"/>
      <inertia ixx="0.00159669309110302" ixy="2.4061978488582E-08" ixz="7.04421309293951E-10" iyy="0.00218039802623776" iyz="4.40635676564146E-06" izz="0.0024879385019285"/>
    </inertial>
    <visual>
      <origin rpy="0 0 0" xyz="0 0 0"/>
      <geometry>
        <mesh filename="package://qm_description/meshes/qudraputed/sirius/difference_bl.STL"/>
      </geometry>
      <material name="">
        <color rgba="1 1 1 1"/>
      </material>
    </visual>
    <!-- <collision>
      <origin
        xyz="0 0 0"
        rpy="0 0 0" />
      <geometry>
        <mesh
          filename="package://qm_description/meshes/qudraputed/$(arg robot_type)/difference_bl.STL" />
      </geometry>
    </collision> -->
  </link>
  <joint name="RH_HAA" type="revolute">
    <origin rpy="0 0 0" xyz="-0.31 -0.05 0"/>
    <parent link="base"/>
    <child link="difference_bl"/>
    <axis xyz="1 0 0"/>
    <dynamics damping="0.0" friction="0.0"/>
    <limit effort="35" lower="-0.7853981633974483" upper="0.7853981633974483" velocity="45"/>
  </joint>
  <link name="thigh_bl">
    <inertial>
      <origin rpy="0 0 0" xyz="-7.79361510050425E-06 -0.0767249033075054 -0.0853108141844979"/>
      <mass value="1.84491923543638"/>
      <inertia ixx="0.02007313377734" ixy="-6.22617105712692E-06" ixz="1.64593347131925E-05" iyy="0.0194374045436634" iyz="-0.00239094217884283" izz="0.00254294323646131"/>
    </inertial>
    <visual>
      <origin rpy="0 0 0" xyz="0 0 0"/>
      <geometry>
        <mesh filename="package://qm_description/meshes/qudraputed/sirius/thigh_bl.STL"/>
      </geometry>
      <material name="">
        <color rgba="0.698039215686274 0.698039215686274 0.698039215686274 1"/>
      </material>
    </visual>
    <collision>
      <origin rpy="0 0 0" xyz="0 -0.093 -0.135"/>
      <geometry>
        <box size="0.05 0.04 0.28"/>
        <!-- <mesh
          filename="package://qm_description/meshes/qudraputed/$(arg robot_type)/thigh_bl.STL" /> -->
      </geometry>
    </collision>
  </link>
  <joint name="RH_HFE" type="revolute">
    <origin rpy="0 0 0" xyz="0 -0.041500000002547 0"/>
    <parent link="difference_bl"/>
    <child link="thigh_bl"/>
    <axis xyz="0 1 0"/>
    <dynamics damping="0.0" friction="0.0"/>
    <limit effort="35" lower="-1.57" upper="1.57" velocity="45"/>
  </joint>
  <link name="shank_bl">
    <inertial>
      <origin rpy="0 0 0" xyz="0.0379180936720101 1.00823110678883E-05 -0.105367936319638"/>
      <mass value="0.46394589693239"/>
      <inertia ixx="0.00629016612495369" ixy="-1.45795393960972E-07" ixz="0.00134757706124343" iyy="0.00676703648463389" iyz="7.3333135362383E-07" izz="0.000568017818729184"/>
    </inertial>
    <visual>
      <origin rpy="0 0 0" xyz="0 0 0"/>
      <geometry>
        <mesh filename="package://qm_description/meshes/qudraputed/sirius/shank_bl.STL"/>
      </geometry>
      <material name="">
        <color rgba="0.698039215686274 0.698039215686274 0.698039215686274 1"/>
      </material>
    </visual>
    <collision>
      <origin rpy="0 0 0" xyz="0.055 0 -0.12"/>
      <geometry>
        <cylinder length="0.25" radius="0.016"/>
        <!-- <mesh
          filename="package://qm_description/meshes/qudraputed/$(arg robot_type)/shank_bl.STL" /> -->
      </geometry>
    </collision>
  </link>
  <joint name="RH_KFE" type="revolute">
    <origin rpy="0 0 0" xyz="0 -0.0931000000000001 -0.270122814075249"/>
    <parent link="thigh_bl"/>
    <child link="shank_bl"/>
    <axis xyz="0 1 0"/>
    <dynamics damping="0.0" friction="0.0"/>
    <limit effort="45" lower="-1.17453292519943295" upper="3.141592653589793" velocity="45"/>
  </joint>
  <link name="RH_FOOT">
    <visual>
      <origin rpy="0 0 0" xyz="0 0 0"/>
      <geometry>
        <sphere radius="0.03"/>
      </geometry>
      <!-- <material name="orange"/> -->
    </visual>
    <collision>
      <origin rpy="0 0 0" xyz="0 0 0"/>
      <geometry>
        <sphere radius="0.03"/>
      </geometry>
    </collision>
    <inertial>
      <mass value="0.06"/>
      <inertia ixx="9.600000000000001e-04" ixy="0.0" ixz="0.0" iyy="9.600000000000001e-04" iyz="0.0" izz="9.600000000000001e-03"/>
    </inertial>
  </link>
  <joint name="RH_FOOT_fixed_joint" type="fixed">
    <origin rpy="0 0 0" xyz="0.07 0 -0.252"/>
    <parent link="shank_bl"/>
    <child link="RH_FOOT"/>
  </joint>
  <transmission name="RH_HAA_tran">
    <type>transmission_interface/SimpleTransmission</type>
    <joint name="RH_HAA">
      <hardwareInterface>hardware_interface/EffortJointInterface</hardwareInterface>
    </joint>
    <actuator name="RH_HAA_motor">
      <hardwareInterface>hardware_interface/EffortJointInterface</hardwareInterface>
      <mechanicalReduction>1</mechanicalReduction>
    </actuator>
  </transmission>
  <transmission name="RH_HFE_tran">
    <type>transmission_interface/SimpleTransmission</type>
    <joint name="RH_HFE">
      <hardwareInterface>hardware_interface/EffortJointInterface</hardwareInterface>
    </joint>
    <actuator name="RH_HFE_motor">
      <hardwareInterface>hardware_interface/EffortJointInterface</hardwareInterface>
      <mechanicalReduction>1</mechanicalReduction>
    </actuator>
  </transmission>
  <transmission name="RH_KFE_tran">
    <type>transmission_interface/SimpleTransmission</type>
    <joint name="RH_KFE">
      <hardwareInterface>hardware_interface/EffortJointInterface</hardwareInterface>
    </joint>
    <actuator name="RH_KFE_motor">
      <hardwareInterface>hardware_interface/EffortJointInterface</hardwareInterface>
      <mechanicalReduction>1</mechanicalReduction>
    </actuator>
  </transmission>
  <link name="base_link">
    <inertial>
      <origin rpy="0 0 0" xyz="0.0030333225964161 -0.000695374211760413 0.0297999913998699"/>
      <mass value="0.786"/>
      <inertia ixx="0.000209638954503881" ixy="1.40428307955712E-06" ixz="5.68689686775343E-06" iyy="0.000199797107592004" iyz="-3.65725364306001E-06" izz="0.00023745988736141"/>
    </inertial>
    <visual>
      <origin rpy="0 0 0" xyz="0 0 0"/>
      <geometry>
        <mesh filename="package://qm_description/meshes/manipulator/a1x/base_link.STL"/>
      </geometry>
      <material name="">
        <color rgba="0.807843137254902 0.843137254901961 0.905882352941176 1"/>
      </material>
    </visual>
    <collision>
      <origin rpy="0 0 0" xyz="0 0 0"/>
      <geometry>
        <mesh filename="package://qm_description/meshes/manipulator/a1x/base_link.STL"/>
      </geometry>
    </collision>
  </link>
  <link name="arm_link1">
    <inertial>
      <origin rpy="0 0 0" xyz="3.42079032877862E-07 -0.00198629091504759 0.0468866154783616"/>
      <mass value="0.839"/>
      <inertia ixx="0.000224145218285449" ixy="-4.77827595565432E-10" ixz="8.43370254611206E-09" iyy="0.000269809362921142" iyz="9.38346508356547E-09" izz="0.000218726872211685"/>
    </inertial>
    <visual>
      <origin rpy="0 0 0" xyz="0 0 0"/>
      <geometry>
        <mesh filename="package://qm_description/meshes/manipulator/a1x/arm_link1.STL"/>
      </geometry>
      <material name="">
        <color rgba="0.807843137254902 0.843137254901961 0.905882352941176 1"/>
      </material>
    </visual>
    <collision>
      <origin rpy="0 0 0" xyz="0 0 0"/>
      <geometry>
        <mesh filename="package://qm_description/meshes/manipulator/a1x/arm_link1.STL"/>
      </geometry>
    </collision>
  </link>
  <joint name="arm_joint1" type="revolute">
    <origin rpy="0 0 0" xyz="0 0 0.08605"/>
    <parent link="base_link"/>
    <child link="arm_link1"/>
    <axis xyz="0 0 1"/>
    <limit effort="27" lower="-2.8798" upper="2.8798" velocity="10.472"/>
  </joint>
  <link name="arm_link2">
    <inertial>
      <origin rpy="0 0 0" xyz="-0.122675172740935 -0.0295384346078661 0.00365030178710546"/>
      <mass value="1.09"/>
      <inertia ixx="0.000388241930413796" ixy="-2.17638982375649E-05" ixz="8.91426532538946E-06" iyy="0.00274637473933513" iyz="1.19748272961647E-06" izz="0.00278012046088806"/>
    </inertial>
    <visual>
      <origin rpy="0 0 0" xyz="0 0 0"/>
      <geometry>
        <mesh filename="package://qm_description/meshes/manipulator/a1x/arm_link2.STL"/>
      </geometry>
      <material name="">
        <color rgba="0.807843137254902 0.843137254901961 0.905882352941176 1"/>
      </material>
    </visual>
    <collision>
      <origin rpy="0 0 0" xyz="0 0 0"/>
      <geometry>
        <mesh filename="package://qm_description/meshes/manipulator/a1x/arm_link2.STL"/>
      </geometry>
    </collision>
  </link>
  <joint name="arm_joint2" type="revolute">
    <origin rpy="0 0 0" xyz="0 0.03075 0.04925"/>
    <parent link="arm_link1"/>
    <child link="arm_link2"/>
    <axis xyz="0 1 0"/>
    <limit effort="50" lower="0" upper="3.1416" velocity="12.5664"/>
  </joint>
  <link name="arm_link3">
    <inertial>
      <origin rpy="0 0 0" xyz="0.0566624793223791 -0.0291316466078999 0.0568018844686509"/>
      <mass value="0.739"/>
      <inertia ixx="0.000257907545256439" ixy="1.02695451350475E-05" ixz="-0.000131693719602983" iyy="0.000671352233244435" iyz="-8.03382534299068E-06" izz="0.000550051611056369"/>
    </inertial>
    <visual>
      <origin rpy="0 0 0" xyz="0 0 0"/>
      <geometry>
        <mesh filename="package://qm_description/meshes/manipulator/a1x/arm_link3.STL"/>
      </geometry>
      <material name="">
        <color rgba="0.807843137254902 0.843137254901961 0.905882352941176 1"/>
      </material>
    </visual>
    <collision>
      <origin rpy="0 0 0" xyz="0 0 0"/>
      <geometry>
        <mesh filename="package://qm_description/meshes/manipulator/a1x/arm_link3.STL"/>
      </geometry>
    </collision>
  </link>
  <joint name="arm_joint3" type="revolute">
    <origin rpy="0 0 0" xyz="-0.3 0.00025004 0"/>
    <parent link="arm_link2"/>
    <child link="arm_link3"/>
    <axis xyz="0 1 0"/>
    <limit effort="27" lower="-3.3161" upper="0" velocity="10.472"/>
  </joint>
  <link name="arm_link4">
    <inertial>
      <origin rpy="0 0 0" xyz="0.0699840030193581 -0.0287504697364447 0.0541968318197228"/>
      <mass value="0.419"/>
      <inertia ixx="6.62006896114572E-05" ixy="-9.3635648969069E-09" ixz="-4.25876556256057E-09" iyy="6.79307239443371E-05" iyz="7.77726883989867E-07" izz="6.69265447808637E-05"/>
    </inertial>
    <visual>
      <origin rpy="0 0 0" xyz="0 0 0"/>
      <geometry>
        <mesh filename="package://qm_description/meshes/manipulator/a1x/arm_link4.STL"/>
      </geometry>
      <material name="">
        <color rgba="0.807843137254902 0.843137254901961 0.905882352941176 1"/>
      </material>
    </visual>
    <collision>
      <origin rpy="0 0 0" xyz="0 0 0"/>
      <geometry>
        <mesh filename="package://qm_description/meshes/manipulator/a1x/arm_link4.STL"/>
      </geometry>
    </collision>
  </link>
  <joint name="arm_joint4" type="revolute">
    <origin rpy="0 0 0" xyz="0.1747 0.00049739 0.075485"/>
    <parent link="arm_link3"/>
    <child link="arm_link4"/>
    <axis xyz="0 1 0"/>
    <limit effort="14" lower="-1.5708" upper="1.5708" velocity="32.9867"/>
  </joint>
  <link name="arm_link5">
    <inertial>
      <origin rpy="0 0 0" xyz="-0.000803198983898074 -2.29028914278118E-07 -0.0402656141956459"/>
      <mass value="0.054"/>
      <inertia ixx="5.80420988761095E-05" ixy="-1.94657864482709E-13" ixz="1.11613844426808E-14" iyy="5.76397557796697E-05" iyz="-3.56183851121823E-11" izz="5.68558379713068E-05"/>
    </inertial>
    <visual>
      <origin rpy="0 0 0" xyz="0 0 0"/>
      <geometry>
        <mesh filename="package://qm_description/meshes/manipulator/a1x/arm_link5.STL"/>
      </geometry>
      <material name="">
        <color rgba="0.807843137254902 0.843137254901961 0.905882352941176 1"/>
      </material>
    </visual>
    <collision>
      <origin rpy="0 0 0" xyz="0 0 0"/>
      <geometry>
        <mesh filename="package://qm_description/meshes/manipulator/a1x/arm_link5.STL"/>
      </geometry>
    </collision>
  </link>
  <joint name="arm_joint5" type="revolute">
    <origin rpy="0 0 0" xyz="0.08 -0.031498 0.0405"/>
    <parent link="arm_link4"/>
    <child link="arm_link5"/>
    <axis xyz="0 0 1"/>
    <limit effort="14" lower="-1.5708" upper="1.5708" velocity="32.9867"/>
  </joint>
  <link name="arm_link6">
    <inertial>
      <origin rpy="0 0 0" xyz="0.00709944426961403 -8.90673146347609E-10 -3.82632235882419E-05"/>
      <mass value="0.031"/>
      <inertia ixx="3.44527427683917E-06" ixy="-2.00656296989553E-13" ixz="-1.26136975189559E-09" iyy="1.82572780689222E-06" iyz="-3.95364679222355E-15" izz="1.81730990577526E-06"/>
    </inertial>
    <visual>
      <origin rpy="0 0 0" xyz="0 0 0"/>
      <geometry>
        <mesh filename="package://qm_description/meshes/manipulator/a1x/arm_link6.STL"/>
      </geometry>
      <material name="">
        <color rgba="0.807843137254902 0.843137254901961 0.905882352941176 1"/>
      </material>
    </visual>
    <collision>
      <origin rpy="0 0 0" xyz="0 0 0"/>
      <geometry>
        <mesh filename="package://qm_description/meshes/manipulator/a1x/arm_link6.STL"/>
      </geometry>
    </collision>
  </link>
  <joint name="arm_joint6" type="revolute">
    <origin rpy="0 0 0" xyz="0.022503 0 -0.0405"/>
    <parent link="arm_link5"/>
    <child link="arm_link6"/>
    <axis xyz="1 0 0"/>
    <limit effort="14" lower="-2.8798" upper="2.8798" velocity="32.9867"/>
  </joint>
  <link name="gripper_link">
    <inertial>
      <origin rpy="0 0 0" xyz="-0.0311072323899603 1.17979991887118E-08 7.93394685505433E-08"/>
      <mass value="0.604"/>
      <inertia ixx="0.000175881544189539" ixy="-6.06026450851008E-11" ixz="5.30643405624365E-10" iyy="9.86379407701341E-05" iyz="-8.18686692495892E-08" izz="0.000165121280580029"/>
    </inertial>
    <visual>
      <origin rpy="0 0 0" xyz="0 0 0"/>
      <geometry>
        <mesh filename="package://qm_description/meshes/manipulator/a1x/gripper_link.STL"/>
      </geometry>
      <material name="">
        <color rgba="0.807843137254902 0.843137254901961 0.905882352941176 1"/>
      </material>
    </visual>
    <collision>
      <origin rpy="0 0 0" xyz="0 0 0"/>
      <geometry>
        <mesh filename="package://qm_description/meshes/manipulator/a1x/gripper_link.STL"/>
      </geometry>
    </collision>
  </link>
  <joint name="gripper_joint" type="fixed">
    <origin rpy="0 0 0" xyz="0.08165 0 0"/>
    <parent link="arm_link6"/>
    <child link="gripper_link"/>
    <axis xyz="0 0 0"/>
  </joint>
  <link name="gripper_finger_link1">
    <inertial>
      <origin rpy="0 0 0" xyz="-0.0195895895552112 -0.0151136845490034 0.00542254359093075"/>
      <mass value="0.020196517310345"/>
      <inertia ixx="2.40569358477209E-06" ixy="3.9898459609048E-07" ixz="5.12152762183641E-08" iyy="5.71079298307516E-06" iyz="6.19467902008363E-08" izz="6.48482183930358E-06"/>
    </inertial>
    <visual>
      <origin rpy="0 0 0" xyz="0 0 0"/>
      <geometry>
        <mesh filename="package://qm_description/meshes/manipulator/a1x/gripper_finger_link1.STL"/>
      </geometry>
      <material name="">
        <color rgba="0.807843137254902 0.843137254901961 0.905882352941176 1"/>
      </material>
    </visual>
    <collision>
      <origin rpy="0 0 0" xyz="0 0 0"/>
      <geometry>
        <mesh filename="package://qm_description/meshes/manipulator/a1x/gripper_finger_link1.STL"/>
      </geometry>
    </collision>
  </link>
  <joint name="gripper_finger_joint1" type="prismatic">
    <origin rpy="0 0 0" xyz="0.03689 0.013453 0.00012059"/>
    <parent link="gripper_link"/>
    <child link="gripper_finger_link1"/>
    <axis xyz="0 1 0"/>
    <limit effort="100" lower="0" upper="0.05" velocity="0.25"/>
  </joint>
  <link name="gripper_finger_link2">
    <inertial>
      <origin rpy="0 0 0" xyz="-0.0195895857999098 0.0151136893508115 -0.00542254357246619"/>
      <mass value="0.0201965174144991"/>
      <inertia ixx="2.40569340151687E-06" ixy="-3.98983784827124E-07" ixz="-5.12152683073981E-08" iyy="5.71079321589929E-06" iyz="6.19467953006536E-08" izz="6.48482187274222E-06"/>
    </inertial>
    <visual>
      <origin rpy="0 0 0" xyz="0 0 0"/>
      <geometry>
        <mesh filename="package://qm_description/meshes/manipulator/a1x/gripper_finger_link2.STL"/>
      </geometry>
      <material name="">
        <color rgba="0.807843137254902 0.843137254901961 0.905882352941176 1"/>
      </material>
    </visual>
    <collision>
      <origin rpy="0 0 0" xyz="0 0 0"/>
      <geometry>
        <mesh filename="package://qm_description/meshes/manipulator/a1x/gripper_finger_link2.STL"/>
      </geometry>
    </collision>
  </link>
  <joint name="gripper_finger_joint2" type="prismatic">
    <origin rpy="0 0 0" xyz="0.03689 -0.013453 -0.00012059"/>
    <parent link="gripper_link"/>
    <child link="gripper_finger_link2"/>
    <axis xyz="0 1 0"/>
    <limit effort="100" lower="-0.05" upper="0" velocity="0.25"/>
  </joint>
  <transmission name="arm_joint1_trans">
    <type>transmission_interface/SimpleTransmission</type>
    <joint name="arm_joint1">
      <hardwareInterface>hardware_interface/EffortJointInterface</hardwareInterface>
    </joint>
    <actuator name="arm_joint1_motor">
      <hardwareInterface>hardware_interface/EffortJointInterface</hardwareInterface>
      <mechanicalReduction>1.0</mechanicalReduction>
    </actuator>
  </transmission>
  <transmission name="arm_joint2_trans">
    <type>transmission_interface/SimpleTransmission</type>
    <joint name="arm_joint2">
      <hardwareInterface>hardware_interface/EffortJointInterface</hardwareInterface>
    </joint>
    <actuator name="arm_joint2_motor">
      <hardwareInterface>hardware_interface/EffortJointInterface</hardwareInterface>
      <mechanicalReduction>1.0</mechanicalReduction>
    </actuator>
  </transmission>
  <transmission name="arm_joint3_trans">
    <type>transmission_interface/SimpleTransmission</type>
    <joint name="arm_joint3">
      <hardwareInterface>hardware_interface/EffortJointInterface</hardwareInterface>
    </joint>
    <actuator name="arm_joint3_motor">
      <hardwareInterface>hardware_interface/EffortJointInterface</hardwareInterface>
      <mechanicalReduction>1.0</mechanicalReduction>
    </actuator>
  </transmission>
  <transmission name="arm_joint4_trans">
    <type>transmission_interface/SimpleTransmission</type>
    <joint name="arm_joint4">
      <hardwareInterface>hardware_interface/EffortJointInterface</hardwareInterface>
    </joint>
    <actuator name="arm_joint4_motor">
      <hardwareInterface>hardware_interface/EffortJointInterface</hardwareInterface>
      <mechanicalReduction>1.0</mechanicalReduction>
    </actuator>
  </transmission>
  <transmission name="arm_joint5_trans">
    <type>transmission_interface/SimpleTransmission</type>
    <joint name="arm_joint5">
      <hardwareInterface>hardware_interface/EffortJointInterface</hardwareInterface>
    </joint>
    <actuator name="arm_joint5_motor">
      <hardwareInterface>hardware_interface/EffortJointInterface</hardwareInterface>
      <mechanicalReduction>1.0</mechanicalReduction>
    </actuator>
  </transmission>
  <transmission name="arm_joint6_trans">
    <type>transmission_interface/SimpleTransmission</type>
    <joint name="arm_joint6">
      <hardwareInterface>hardware_interface/EffortJointInterface</hardwareInterface>
    </joint>
    <actuator name="arm_joint6_motor">
      <hardwareInterface>hardware_interface/EffortJointInterface</hardwareInterface>
      <mechanicalReduction>1.0</mechanicalReduction>
    </actuator>
  </transmission>
  <!-- for gazebo -->
  <!-- <link name="world"/>
  
  <joint name="connect_root_and_world" type="fixed">
    <child link="base_link" />
    <parent link="world" />
    <origin xyz="0 0 0" rpy="0 0 0" />    
  </joint>  -->
  <!-- end effector -->
  <link name="a1x_end_effector"/>
  <joint name="a1x_joint_end_effector" type="fixed">
    <child link="a1x_end_effector"/>
    <parent link="gripper_link"/>
    <origin rpy="0 0 0" xyz="0 0 0"/>
  </joint>
  <joint name="manipulator_joint" type="fixed">
    <parent link="base"/>
    <child link="base_link"/>
    <origin rpy="0.0 0.0 0.0" xyz="0.0 0.0 0.01"/>
  </joint>
  <!-- ros_control plugin -->
  <gazebo>
    <plugin filename="libqm_hw_sim.so" name="gazebo_ros_control">
      <robotNamespace>/</robotNamespace>
      <robotParam>qm_description</robotParam>
      <robotSimType>qm_gazebo/QMMpcHwSim</robotSimType>
    </plugin>
  </gazebo>
</robot>
